<?xml version="1.0"?>
<!--URDF MODEL only arms-->
<robot xmlns:xacro="http://wiki.ros.org/xacro">
  <xacro:macro name="mobile_base"
  params="mobile parent child">

<xacro:unless value="${mobile}">
<joint name="base_joint" type="fixed">
  <origin xyz="0 0 0.2" rpy="0 0 0" />
  <parent link="${parent}" />
  <child link="${child}" />
</joint>
</xacro:unless>

<xacro:if value="${mobile}">
<joint name="joint_traslx" type="prismatic">
  <origin xyz="0 0 0" rpy="0 0 0"/>
  <parent link="${parent}"/>
  <child link="base_f1"/>
  <dynamics damping="0.1" friction="0.1"/>
  <limit effort="3000" velocity="2.0" lower="-2" upper="2" />
  <axis xyz="1 0 0" />
</joint>
<link name="base_f1" />

<joint name="joint_trasly" type="prismatic">
  <origin xyz="0 0 0" rpy="0 0 0"/>
  <parent link="base_f1"/>
  <child link="base_f2"/>
  <dynamics damping="0.1" friction="0.1"/>
  <limit effort="3000" velocity="2.0" lower="-2" upper="2" />
  <axis xyz="0 1 0" />
</joint>
<link name="base_f2" />

<joint name="a_fixed" type="fixed">
  <origin xyz="0 0 0.2" rpy="0 0 0" />
  <parent link="base_f2" />
  <child link="${child}" />
</joint>
</xacro:if>

</xacro:macro>

</robot>
