<?xml version="1.0" ?>
<!-- =================================================================================== -->
<!-- |    This document was autogenerated by xacro from /home/jacobi/projects/cells_ws/src/high_dof_robots/high_dof_description/urdf/mobile_cell_2imm.urdf.xacro | -->
<!-- |    EDITING THIS FILE BY HAND IS NOT RECOMMENDED                                 | -->
<!-- =================================================================================== -->
<!--URDF MODEL 13 DoFs-->
<robot name="cell">
    <link name="world" />
    <link name="home_imm2" />
    <joint name="home_imm2_joint" type="fixed">
        <origin rpy="0 0 0" xyz="2.5 0 0" />
        <parent link="world" />
        <child link="home_imm2" />
    </joint>
    <joint name="imm1_mobile_joint_traslx" type="prismatic">
        <origin rpy="0 0 0" xyz="0 0 0" />
        <parent link="world" />
        <child link="imm1_base_f1" />
        <dynamics damping="0.1" friction="0.1" />
        <limit effort="3000" lower="-30.0" upper="30.0" velocity="1.0" />
        <axis xyz="1 0 0" />
    </joint>
    <link name="imm1_base_f1" />
    <joint name="imm1_mobile_joint_trasly" type="prismatic">
        <origin rpy="0 0 0" xyz="0 0 0" />
        <parent link="imm1_base_f1" />
        <child link="imm1_base_f2" />
        <dynamics damping="0.1" friction="0.1" />
        <limit effort="3000" lower="-30.0" upper="30.0" velocity="1.0" />
        <axis xyz="0 1 0" />
    </joint>
    <link name="imm1_base_f2" />
    <joint name="imm1_mobile_joint_rotz" type="revolute">
        <origin rpy="0 0 0" xyz="0 0 0" />
        <parent link="imm1_base_f2" />
        <child link="imm1_base_f3" />
        <dynamics damping="0.1" friction="0.1" />
        <limit effort="3000" lower="-3.141592653589793" upper="3.141592653589793" velocity="2.0" />
        <axis xyz="0 0 1" />
    </joint>
    <link name="imm1_base_f3">
        <inertial>
            <mass value="30.0" />
            <origin rpy="0 0 0" xyz="0 0 0" />
            <inertia ixx="0.01" ixy="0" ixz="0" iyy="0.01" iyz="0" izz="0.5" />
        </inertial>
        <visual>
            <origin rpy="0 0 0" xyz="0 0 0.3" />
            <geometry>
                <box size="1.2 1 0.6" />
            </geometry>
            <material name="Cyan">
                <color rgba="0 1.0 1.0 1.0" />
            </material>
        </visual>
        <collision>
            <origin rpy="0 0 0" xyz="0 0 0.3" />
            <geometry>
                <box size="1.2 1 0.6" />
            </geometry>
            <material name="Cyan">
                <color rgba="0 1.0 1.0 1.0" />
            </material>
        </collision>
    </link>
    <joint name="imm1_mobile_a_fixed" type="fixed">
        <origin rpy="0 0 0" xyz="0.1 0 0.6" />
        <parent link="imm1_base_f3" />
        <child link="imm1_a_mount_flange" />
    </joint>
    <link name="imm1_a_mount_flange">
        <inertial>
            <mass value="0.01" />
            <origin rpy="0 0 0" xyz="0 0 0" />
            <inertia ixx="0.01" ixy="0" ixz="0" iyy="0.01" iyz="0" izz="0.01" />
        </inertial>
    </link>
    <joint name="imm1_a_joint_1" type="revolute">
        <origin rpy="-1.5707963267948966 0 0" xyz="0 0 0" />
        <parent link="imm1_a_mount_flange" />
        <child link="imm1_a_upper_arm_f1" />
        <dynamics damping="0.1" friction="0.1" />
        <limit effort="3000000" lower="-1.5708" upper="1.5708" velocity="10.0" />
        <axis xyz="0 0 1" />
        <dynamics damping="0.7" />
    </joint>
    <link name="imm1_a_upper_arm_f1">
        <inertial>
            <mass value="0.01" />
            <origin rpy="0 0 0" xyz="0 0 0" />
            <inertia ixx="0.01" ixy="0" ixz="0" iyy="0.01" iyz="0" izz="0.01" />
        </inertial>
    </link>
    <joint name="imm1_a_joint_2" type="revolute">
        <origin rpy="0 0 0" xyz="0 0 0" />
        <parent link="imm1_a_upper_arm_f1" />
        <child link="imm1_a_upper_arm" />
        <dynamics damping="0.1" friction="0.1" />
        <limit effort="3000000" lower="-1.5708" upper="1.5708" velocity="10.0" />
        <axis xyz="1 0 0" />
        <dynamics damping="0.7" />
    </joint>
    <link name="imm1_a_upper_arm">
        <inertial>
            <mass value="3.25" />
            <origin rpy="0 0 0" xyz="0 0 0" />
            <inertia ixx="0.019063" ixy="0" ixz="0" iyy="0.0013033" iyz="0" izz="0.019063" />
        </inertial>
        <visual>
            <origin rpy="1.5708 0 0" xyz="0 -0.25 0" />
            <geometry>
                <cylinder length="0.5" radius="0.1" />
            </geometry>
            <material name="blue">
                <color rgba="0.0 0.0 0.8 1.0" />
            </material>
        </visual>
        <collision>
            <origin rpy="1.5708 0 0" xyz="0 -0.25 0" />
            <geometry>
                <cylinder length="0.5" radius="0.1" />
            </geometry>
        </collision>
    </link>
    <joint name="imm1_a_joint_3" type="revolute">
        <origin rpy="0 0 0" xyz="0 -0.5 0" />
        <parent link="imm1_a_upper_arm" />
        <child link="imm1_a_forearm" />
        <dynamics damping="0.1" friction="0.1" />
        <limit effort="3000000" lower="-1.5708" upper="1.5708" velocity="10.0" />
        <axis xyz="1 0 0" />
        <dynamics damping="0.7" />
    </joint>
    <link name="imm1_a_forearm">
        <inertial>
            <mass value="2.6" />
            <origin rpy="0 0 0" xyz="0 0 0" />
            <inertia ixx="0.0084595" ixy="0" ixz="0" iyy="0.00038616" iyz="0" izz="0.0084595" />
        </inertial>
        <visual>
            <origin rpy="1.5708 0 0" xyz="0 -0.25 0" />
            <geometry>
                <cylinder length="0.5" radius="0.1" />
            </geometry>
            <material name="grey">
                <color rgba="0.8 0.8 0.8 1.0" />
            </material>
        </visual>
        <collision>
            <origin rpy="1.5708 0 0" xyz="0 -0.25 0" />
            <geometry>
                <cylinder length="0.5" radius="0.1" />
            </geometry>
        </collision>
    </link>
    <joint name="imm1_a_elbow_joint" type="fixed">
        <origin rpy="1.5707963267948966 0 0" xyz="0 -0.5 0" />
        <parent link="imm1_a_forearm" />
        <child link="imm1_a_flange" />
    </joint>
    <link name="imm1_a_flange">
        <inertial>
            <mass value="0.01" />
            <origin rpy="0 0 0" xyz="0 0 0" />
            <inertia ixx="0.01" ixy="0" ixz="0" iyy="0.01" iyz="0" izz="0.01" />
        </inertial>
    </link>
    <transmission name="imm1_a_tran_1">
        <type>transmission_interface/SimpleTransmission</type>
        <joint name="imm1_a_joint_1">
            <hardwareInterface>hardware_interface/EffortJointInterface</hardwareInterface>
        </joint>
        <actuator name="imm1_a_motor_1">
            <hardwareInterface>hardware_interface/EffortJointInterface</hardwareInterface>
            <mechanicalReduction>1</mechanicalReduction>
        </actuator>
    </transmission>
    <transmission name="imm1_a_tran_2">
        <type>transmission_interface/SimpleTransmission</type>
        <joint name="imm1_a_joint_2">
            <hardwareInterface>hardware_interface/EffortJointInterface</hardwareInterface>
        </joint>
        <actuator name="imm1_a_motor_2">
            <hardwareInterface>hardware_interface/EffortJointInterface</hardwareInterface>
            <mechanicalReduction>1</mechanicalReduction>
        </actuator>
    </transmission>
    <transmission name="imm1_a_tran_3">
        <type>transmission_interface/SimpleTransmission</type>
        <joint name="imm1_a_joint_3">
            <hardwareInterface>hardware_interface/EffortJointInterface</hardwareInterface>
        </joint>
        <actuator name="imm1_a_motor_3">
            <hardwareInterface>hardware_interface/EffortJointInterface</hardwareInterface>
            <mechanicalReduction>1</mechanicalReduction>
        </actuator>
    </transmission>
    <!-- Link1 -->
    <gazebo reference="imm1_a_upper_arm">
        <material>Gazebo/Blue</material>
        <plugin name="gazebo_ros_control">
            <robotNamespace>/</robotNamespace>
        </plugin>
    </gazebo>
    <gazebo reference="imm1_a_forearm">
        <material>Gazebo/Grey</material>
    </gazebo>
    <gazebo reference="imm1_a_elbow_joint">
        <provideFeedback>true</provideFeedback>
        <disableFixedJointLumping>true</disableFixedJointLumping>
        <preserveFixedJoint>true</preserveFixedJoint>
    </gazebo>
    <gazebo>
        <plugin filename="libgazebo_ros_ft_sensor.so" name="ft_sensor">
            <updateRate>10.0</updateRate>
            <topicName>imm1_a_flange/wrench</topicName>
            <jointName>imm1_a_elbow_joint</jointName>
        </plugin>
    </gazebo>
    <joint name="imm1_b_fixed" type="fixed">
        <origin rpy="0 0 0" xyz="0 0 0" />
        <parent link="imm1_a_flange" />
        <child link="imm1_b_mount_flange" />
    </joint>
    <link name="imm1_b_mount_flange">
        <inertial>
            <mass value="0.01" />
            <origin rpy="0 0 0" xyz="0 0 0" />
            <inertia ixx="0.01" ixy="0" ixz="0" iyy="0.01" iyz="0" izz="0.01" />
        </inertial>
    </link>
    <joint name="imm1_b_joint_1" type="revolute">
        <origin rpy="-1.5707963267948966 0 0" xyz="0 0 0" />
        <parent link="imm1_b_mount_flange" />
        <child link="imm1_b_upper_arm_f1" />
        <dynamics damping="0.1" friction="0.1" />
        <limit effort="3000000" lower="-1.5708" upper="1.5708" velocity="10.0" />
        <axis xyz="0 0 1" />
        <dynamics damping="0.7" />
    </joint>
    <link name="imm1_b_upper_arm_f1">
        <inertial>
            <mass value="0.01" />
            <origin rpy="0 0 0" xyz="0 0 0" />
            <inertia ixx="0.01" ixy="0" ixz="0" iyy="0.01" iyz="0" izz="0.01" />
        </inertial>
    </link>
    <joint name="imm1_b_joint_2" type="revolute">
        <origin rpy="0 0 0" xyz="0 0 0" />
        <parent link="imm1_b_upper_arm_f1" />
        <child link="imm1_b_upper_arm" />
        <dynamics damping="0.1" friction="0.1" />
        <limit effort="3000000" lower="-1.5708" upper="1.5708" velocity="10.0" />
        <axis xyz="1 0 0" />
        <dynamics damping="0.7" />
    </joint>
    <link name="imm1_b_upper_arm">
        <inertial>
            <mass value="3.25" />
            <origin rpy="0 0 0" xyz="0 0 0" />
            <inertia ixx="0.019063" ixy="0" ixz="0" iyy="0.0013033" iyz="0" izz="0.019063" />
        </inertial>
        <visual>
            <origin rpy="1.5708 0 0" xyz="0 -0.25 0" />
            <geometry>
                <cylinder length="0.5" radius="0.1" />
            </geometry>
            <material name="blue">
                <color rgba="0.0 0.0 0.8 1.0" />
            </material>
        </visual>
        <collision>
            <origin rpy="1.5708 0 0" xyz="0 -0.25 0" />
            <geometry>
                <cylinder length="0.5" radius="0.1" />
            </geometry>
        </collision>
    </link>
    <joint name="imm1_b_joint_3" type="revolute">
        <origin rpy="0 0 0" xyz="0 -0.5 0" />
        <parent link="imm1_b_upper_arm" />
        <child link="imm1_b_forearm" />
        <dynamics damping="0.1" friction="0.1" />
        <limit effort="3000000" lower="-1.5708" upper="1.5708" velocity="10.0" />
        <axis xyz="1 0 0" />
        <dynamics damping="0.7" />
    </joint>
    <link name="imm1_b_forearm">
        <inertial>
            <mass value="2.6" />
            <origin rpy="0 0 0" xyz="0 0 0" />
            <inertia ixx="0.0084595" ixy="0" ixz="0" iyy="0.00038616" iyz="0" izz="0.0084595" />
        </inertial>
        <visual>
            <origin rpy="1.5708 0 0" xyz="0 -0.25 0" />
            <geometry>
                <cylinder length="0.5" radius="0.1" />
            </geometry>
            <material name="grey">
                <color rgba="0.8 0.8 0.8 1.0" />
            </material>
        </visual>
        <collision>
            <origin rpy="1.5708 0 0" xyz="0 -0.25 0" />
            <geometry>
                <cylinder length="0.5" radius="0.1" />
            </geometry>
        </collision>
    </link>
    <joint name="imm1_b_elbow_joint" type="fixed">
        <origin rpy="1.5707963267948966 0 0" xyz="0 -0.5 0" />
        <parent link="imm1_b_forearm" />
        <child link="imm1_b_flange" />
    </joint>
    <link name="imm1_b_flange">
        <inertial>
            <mass value="0.01" />
            <origin rpy="0 0 0" xyz="0 0 0" />
            <inertia ixx="0.01" ixy="0" ixz="0" iyy="0.01" iyz="0" izz="0.01" />
        </inertial>
    </link>
    <transmission name="imm1_b_tran_1">
        <type>transmission_interface/SimpleTransmission</type>
        <joint name="imm1_b_joint_1">
            <hardwareInterface>hardware_interface/EffortJointInterface</hardwareInterface>
        </joint>
        <actuator name="imm1_b_motor_1">
            <hardwareInterface>hardware_interface/EffortJointInterface</hardwareInterface>
            <mechanicalReduction>1</mechanicalReduction>
        </actuator>
    </transmission>
    <transmission name="imm1_b_tran_2">
        <type>transmission_interface/SimpleTransmission</type>
        <joint name="imm1_b_joint_2">
            <hardwareInterface>hardware_interface/EffortJointInterface</hardwareInterface>
        </joint>
        <actuator name="imm1_b_motor_2">
            <hardwareInterface>hardware_interface/EffortJointInterface</hardwareInterface>
            <mechanicalReduction>1</mechanicalReduction>
        </actuator>
    </transmission>
    <transmission name="imm1_b_tran_3">
        <type>transmission_interface/SimpleTransmission</type>
        <joint name="imm1_b_joint_3">
            <hardwareInterface>hardware_interface/EffortJointInterface</hardwareInterface>
        </joint>
        <actuator name="imm1_b_motor_3">
            <hardwareInterface>hardware_interface/EffortJointInterface</hardwareInterface>
            <mechanicalReduction>1</mechanicalReduction>
        </actuator>
    </transmission>
    <!-- Link1 -->
    <gazebo reference="imm1_b_upper_arm">
        <material>Gazebo/Blue</material>
    </gazebo>
    <gazebo reference="imm1_b_forearm">
        <material>Gazebo/Grey</material>
    </gazebo>
    <gazebo reference="imm1_b_elbow_joint">
        <provideFeedback>true</provideFeedback>
        <disableFixedJointLumping>true</disableFixedJointLumping>
        <preserveFixedJoint>true</preserveFixedJoint>
    </gazebo>
    <gazebo>
        <plugin filename="libgazebo_ros_ft_sensor.so" name="ft_sensor">
            <updateRate>10.0</updateRate>
            <topicName>imm1_b_flange/wrench</topicName>
            <jointName>imm1_b_elbow_joint</jointName>
        </plugin>
    </gazebo>
    <joint name="imm1_last_flange_joint" type="fixed">
        <origin rpy="0 0 0" xyz="0 0 0" />
        <parent link="imm1_b_flange" />
        <child link="imm1_flange" />
    </joint>
    <link name="imm1_flange" />
    <joint name="imm2_mobile_joint_traslx" type="prismatic">
        <origin rpy="0 0 0" xyz="0 0 0" />
        <parent link="home_imm2" />
        <child link="imm2_base_f1" />
        <dynamics damping="0.1" friction="0.1" />
        <limit effort="3000" lower="-30.0" upper="30.0" velocity="1.0" />
        <axis xyz="1 0 0" />
    </joint>
    <link name="imm2_base_f1" />
    <joint name="imm2_mobile_joint_trasly" type="prismatic">
        <origin rpy="0 0 0" xyz="0 0 0" />
        <parent link="imm2_base_f1" />
        <child link="imm2_base_f2" />
        <dynamics damping="0.1" friction="0.1" />
        <limit effort="3000" lower="-30.0" upper="30.0" velocity="1.0" />
        <axis xyz="0 1 0" />
    </joint>
    <link name="imm2_base_f2" />
    <joint name="imm2_mobile_joint_rotz" type="revolute">
        <origin rpy="0 0 0" xyz="0 0 0" />
        <parent link="imm2_base_f2" />
        <child link="imm2_base_f3" />
        <dynamics damping="0.1" friction="0.1" />
        <limit effort="3000" lower="-3.141592653589793" upper="3.141592653589793" velocity="2.0" />
        <axis xyz="0 0 1" />
    </joint>
    <link name="imm2_base_f3">
        <inertial>
            <mass value="30.0" />
            <origin rpy="0 0 0" xyz="0 0 0" />
            <inertia ixx="0.01" ixy="0" ixz="0" iyy="0.01" iyz="0" izz="0.5" />
        </inertial>
        <visual>
            <origin rpy="0 0 0" xyz="0 0 0.3" />
            <geometry>
                <box size="1.2 1 0.6" />
            </geometry>
            <material name="Cyan">
                <color rgba="0 1.0 1.0 1.0" />
            </material>
        </visual>
        <collision>
            <origin rpy="0 0 0" xyz="0 0 0.3" />
            <geometry>
                <box size="1.2 1 0.6" />
            </geometry>
            <material name="Cyan">
                <color rgba="0 1.0 1.0 1.0" />
            </material>
        </collision>
    </link>
    <joint name="imm2_mobile_a_fixed" type="fixed">
        <origin rpy="0 0 0" xyz="0.1 0 0.6" />
        <parent link="imm2_base_f3" />
        <child link="imm2_a_mount_flange" />
    </joint>
    <link name="imm2_a_mount_flange">
        <inertial>
            <mass value="0.01" />
            <origin rpy="0 0 0" xyz="0 0 0" />
            <inertia ixx="0.01" ixy="0" ixz="0" iyy="0.01" iyz="0" izz="0.01" />
        </inertial>
    </link>
    <joint name="imm2_a_joint_1" type="revolute">
        <origin rpy="-1.5707963267948966 0 0" xyz="0 0 0" />
        <parent link="imm2_a_mount_flange" />
        <child link="imm2_a_upper_arm_f1" />
        <dynamics damping="0.1" friction="0.1" />
        <limit effort="3000000" lower="-1.5708" upper="1.5708" velocity="10.0" />
        <axis xyz="0 0 1" />
        <dynamics damping="0.7" />
    </joint>
    <link name="imm2_a_upper_arm_f1">
        <inertial>
            <mass value="0.01" />
            <origin rpy="0 0 0" xyz="0 0 0" />
            <inertia ixx="0.01" ixy="0" ixz="0" iyy="0.01" iyz="0" izz="0.01" />
        </inertial>
    </link>
    <joint name="imm2_a_joint_2" type="revolute">
        <origin rpy="0 0 0" xyz="0 0 0" />
        <parent link="imm2_a_upper_arm_f1" />
        <child link="imm2_a_upper_arm" />
        <dynamics damping="0.1" friction="0.1" />
        <limit effort="3000000" lower="-1.5708" upper="1.5708" velocity="10.0" />
        <axis xyz="1 0 0" />
        <dynamics damping="0.7" />
    </joint>
    <link name="imm2_a_upper_arm">
        <inertial>
            <mass value="3.25" />
            <origin rpy="0 0 0" xyz="0 0 0" />
            <inertia ixx="0.019063" ixy="0" ixz="0" iyy="0.0013033" iyz="0" izz="0.019063" />
        </inertial>
        <visual>
            <origin rpy="1.5708 0 0" xyz="0 -0.25 0" />
            <geometry>
                <cylinder length="0.5" radius="0.1" />
            </geometry>
            <material name="blue">
                <color rgba="0.0 0.0 0.8 1.0" />
            </material>
        </visual>
        <collision>
            <origin rpy="1.5708 0 0" xyz="0 -0.25 0" />
            <geometry>
                <cylinder length="0.5" radius="0.1" />
            </geometry>
        </collision>
    </link>
    <joint name="imm2_a_joint_3" type="revolute">
        <origin rpy="0 0 0" xyz="0 -0.5 0" />
        <parent link="imm2_a_upper_arm" />
        <child link="imm2_a_forearm" />
        <dynamics damping="0.1" friction="0.1" />
        <limit effort="3000000" lower="-1.5708" upper="1.5708" velocity="10.0" />
        <axis xyz="1 0 0" />
        <dynamics damping="0.7" />
    </joint>
    <link name="imm2_a_forearm">
        <inertial>
            <mass value="2.6" />
            <origin rpy="0 0 0" xyz="0 0 0" />
            <inertia ixx="0.0084595" ixy="0" ixz="0" iyy="0.00038616" iyz="0" izz="0.0084595" />
        </inertial>
        <visual>
            <origin rpy="1.5708 0 0" xyz="0 -0.25 0" />
            <geometry>
                <cylinder length="0.5" radius="0.1" />
            </geometry>
            <material name="grey">
                <color rgba="0.8 0.8 0.8 1.0" />
            </material>
        </visual>
        <collision>
            <origin rpy="1.5708 0 0" xyz="0 -0.25 0" />
            <geometry>
                <cylinder length="0.5" radius="0.1" />
            </geometry>
        </collision>
    </link>
    <joint name="imm2_a_elbow_joint" type="fixed">
        <origin rpy="1.5707963267948966 0 0" xyz="0 -0.5 0" />
        <parent link="imm2_a_forearm" />
        <child link="imm2_a_flange" />
    </joint>
    <link name="imm2_a_flange">
        <inertial>
            <mass value="0.01" />
            <origin rpy="0 0 0" xyz="0 0 0" />
            <inertia ixx="0.01" ixy="0" ixz="0" iyy="0.01" iyz="0" izz="0.01" />
        </inertial>
    </link>
    <transmission name="imm2_a_tran_1">
        <type>transmission_interface/SimpleTransmission</type>
        <joint name="imm2_a_joint_1">
            <hardwareInterface>hardware_interface/EffortJointInterface</hardwareInterface>
        </joint>
        <actuator name="imm2_a_motor_1">
            <hardwareInterface>hardware_interface/EffortJointInterface</hardwareInterface>
            <mechanicalReduction>1</mechanicalReduction>
        </actuator>
    </transmission>
    <transmission name="imm2_a_tran_2">
        <type>transmission_interface/SimpleTransmission</type>
        <joint name="imm2_a_joint_2">
            <hardwareInterface>hardware_interface/EffortJointInterface</hardwareInterface>
        </joint>
        <actuator name="imm2_a_motor_2">
            <hardwareInterface>hardware_interface/EffortJointInterface</hardwareInterface>
            <mechanicalReduction>1</mechanicalReduction>
        </actuator>
    </transmission>
    <transmission name="imm2_a_tran_3">
        <type>transmission_interface/SimpleTransmission</type>
        <joint name="imm2_a_joint_3">
            <hardwareInterface>hardware_interface/EffortJointInterface</hardwareInterface>
        </joint>
        <actuator name="imm2_a_motor_3">
            <hardwareInterface>hardware_interface/EffortJointInterface</hardwareInterface>
            <mechanicalReduction>1</mechanicalReduction>
        </actuator>
    </transmission>
    <!-- Link1 -->
    <gazebo reference="imm2_a_upper_arm">
        <material>Gazebo/Blue</material>
    </gazebo>
    <gazebo reference="imm2_a_forearm">
        <material>Gazebo/Grey</material>
    </gazebo>
    <gazebo reference="imm2_a_elbow_joint">
        <provideFeedback>true</provideFeedback>
        <disableFixedJointLumping>true</disableFixedJointLumping>
        <preserveFixedJoint>true</preserveFixedJoint>
    </gazebo>
    <gazebo>
        <plugin filename="libgazebo_ros_ft_sensor.so" name="ft_sensor">
            <updateRate>10.0</updateRate>
            <topicName>imm2_a_flange/wrench</topicName>
            <jointName>imm2_a_elbow_joint</jointName>
        </plugin>
    </gazebo>
    <joint name="imm2_b_fixed" type="fixed">
        <origin rpy="0 0 0" xyz="0 0 0" />
        <parent link="imm2_a_flange" />
        <child link="imm2_b_mount_flange" />
    </joint>
    <link name="imm2_b_mount_flange">
        <inertial>
            <mass value="0.01" />
            <origin rpy="0 0 0" xyz="0 0 0" />
            <inertia ixx="0.01" ixy="0" ixz="0" iyy="0.01" iyz="0" izz="0.01" />
        </inertial>
    </link>
    <joint name="imm2_b_joint_1" type="revolute">
        <origin rpy="-1.5707963267948966 0 0" xyz="0 0 0" />
        <parent link="imm2_b_mount_flange" />
        <child link="imm2_b_upper_arm_f1" />
        <dynamics damping="0.1" friction="0.1" />
        <limit effort="3000000" lower="-1.5708" upper="1.5708" velocity="10.0" />
        <axis xyz="0 0 1" />
        <dynamics damping="0.7" />
    </joint>
    <link name="imm2_b_upper_arm_f1">
        <inertial>
            <mass value="0.01" />
            <origin rpy="0 0 0" xyz="0 0 0" />
            <inertia ixx="0.01" ixy="0" ixz="0" iyy="0.01" iyz="0" izz="0.01" />
        </inertial>
    </link>
    <joint name="imm2_b_joint_2" type="revolute">
        <origin rpy="0 0 0" xyz="0 0 0" />
        <parent link="imm2_b_upper_arm_f1" />
        <child link="imm2_b_upper_arm" />
        <dynamics damping="0.1" friction="0.1" />
        <limit effort="3000000" lower="-1.5708" upper="1.5708" velocity="10.0" />
        <axis xyz="1 0 0" />
        <dynamics damping="0.7" />
    </joint>
    <link name="imm2_b_upper_arm">
        <inertial>
            <mass value="3.25" />
            <origin rpy="0 0 0" xyz="0 0 0" />
            <inertia ixx="0.019063" ixy="0" ixz="0" iyy="0.0013033" iyz="0" izz="0.019063" />
        </inertial>
        <visual>
            <origin rpy="1.5708 0 0" xyz="0 -0.25 0" />
            <geometry>
                <cylinder length="0.5" radius="0.1" />
            </geometry>
            <material name="blue">
                <color rgba="0.0 0.0 0.8 1.0" />
            </material>
        </visual>
        <collision>
            <origin rpy="1.5708 0 0" xyz="0 -0.25 0" />
            <geometry>
                <cylinder length="0.5" radius="0.1" />
            </geometry>
        </collision>
    </link>
    <joint name="imm2_b_joint_3" type="revolute">
        <origin rpy="0 0 0" xyz="0 -0.5 0" />
        <parent link="imm2_b_upper_arm" />
        <child link="imm2_b_forearm" />
        <dynamics damping="0.1" friction="0.1" />
        <limit effort="3000000" lower="-1.5708" upper="1.5708" velocity="10.0" />
        <axis xyz="1 0 0" />
        <dynamics damping="0.7" />
    </joint>
    <link name="imm2_b_forearm">
        <inertial>
            <mass value="2.6" />
            <origin rpy="0 0 0" xyz="0 0 0" />
            <inertia ixx="0.0084595" ixy="0" ixz="0" iyy="0.00038616" iyz="0" izz="0.0084595" />
        </inertial>
        <visual>
            <origin rpy="1.5708 0 0" xyz="0 -0.25 0" />
            <geometry>
                <cylinder length="0.5" radius="0.1" />
            </geometry>
            <material name="grey">
                <color rgba="0.8 0.8 0.8 1.0" />
            </material>
        </visual>
        <collision>
            <origin rpy="1.5708 0 0" xyz="0 -0.25 0" />
            <geometry>
                <cylinder length="0.5" radius="0.1" />
            </geometry>
        </collision>
    </link>
    <joint name="imm2_b_elbow_joint" type="fixed">
        <origin rpy="1.5707963267948966 0 0" xyz="0 -0.5 0" />
        <parent link="imm2_b_forearm" />
        <child link="imm2_b_flange" />
    </joint>
    <link name="imm2_b_flange">
        <inertial>
            <mass value="0.01" />
            <origin rpy="0 0 0" xyz="0 0 0" />
            <inertia ixx="0.01" ixy="0" ixz="0" iyy="0.01" iyz="0" izz="0.01" />
        </inertial>
    </link>
    <transmission name="imm2_b_tran_1">
        <type>transmission_interface/SimpleTransmission</type>
        <joint name="imm2_b_joint_1">
            <hardwareInterface>hardware_interface/EffortJointInterface</hardwareInterface>
        </joint>
        <actuator name="imm2_b_motor_1">
            <hardwareInterface>hardware_interface/EffortJointInterface</hardwareInterface>
            <mechanicalReduction>1</mechanicalReduction>
        </actuator>
    </transmission>
    <transmission name="imm2_b_tran_2">
        <type>transmission_interface/SimpleTransmission</type>
        <joint name="imm2_b_joint_2">
            <hardwareInterface>hardware_interface/EffortJointInterface</hardwareInterface>
        </joint>
        <actuator name="imm2_b_motor_2">
            <hardwareInterface>hardware_interface/EffortJointInterface</hardwareInterface>
            <mechanicalReduction>1</mechanicalReduction>
        </actuator>
    </transmission>
    <transmission name="imm2_b_tran_3">
        <type>transmission_interface/SimpleTransmission</type>
        <joint name="imm2_b_joint_3">
            <hardwareInterface>hardware_interface/EffortJointInterface</hardwareInterface>
        </joint>
        <actuator name="imm2_b_motor_3">
            <hardwareInterface>hardware_interface/EffortJointInterface</hardwareInterface>
            <mechanicalReduction>1</mechanicalReduction>
        </actuator>
    </transmission>
    <!-- Link1 -->
    <gazebo reference="imm2_b_upper_arm">
        <material>Gazebo/Blue</material>
    </gazebo>
    <gazebo reference="imm2_b_forearm">
        <material>Gazebo/Grey</material>
    </gazebo>
    <gazebo reference="imm2_b_elbow_joint">
        <provideFeedback>true</provideFeedback>
        <disableFixedJointLumping>true</disableFixedJointLumping>
        <preserveFixedJoint>true</preserveFixedJoint>
    </gazebo>
    <gazebo>
        <plugin filename="libgazebo_ros_ft_sensor.so" name="ft_sensor">
            <updateRate>10.0</updateRate>
            <topicName>imm2_b_flange/wrench</topicName>
            <jointName>imm2_b_elbow_joint</jointName>
        </plugin>
    </gazebo>
    <joint name="imm2_last_flange_joint" type="fixed">
        <origin rpy="0 0 0" xyz="0 0 0" />
        <parent link="imm2_b_flange" />
        <child link="imm2_flange" />
    </joint>
    <link name="imm2_flange" />
    <gazebo>
        <plugin filename="libgazebo_ros_control.so" name="gazebo_ros_control">
            <robotNamespace>/manipulator</robotNamespace>
            <robotSimType>gazebo_ros_control/DefaultRobotHWSim</robotSimType>
        </plugin>
    </gazebo>
    <transmission name="trans_imm1_mobile_joint_traslx">
        <type>transmission_interface/SimpleTransmission</type>
        <joint name="imm1_mobile_joint_traslx">
            <hardwareInterface>hardware_interface/EffortJointInterface</hardwareInterface>
        </joint>
        <actuator name="imm1_mobile_joint_traslx_motor">
            <hardwareInterface>hardware_interface/EffortJointInterface</hardwareInterface>
            <mechanicalReduction>1</mechanicalReduction>
        </actuator>
    </transmission>
    <transmission name="trans_imm1_mobile_joint_trasly">
        <type>transmission_interface/SimpleTransmission</type>
        <joint name="imm1_mobile_joint_trasly">
            <hardwareInterface>hardware_interface/EffortJointInterface</hardwareInterface>
        </joint>
        <actuator name="imm1_mobile_joint_trasly_motor">
            <hardwareInterface>hardware_interface/EffortJointInterface</hardwareInterface>
            <mechanicalReduction>1</mechanicalReduction>
        </actuator>
    </transmission>
    <transmission name="trans_imm1_mobile_joint_rotz">
        <type>transmission_interface/SimpleTransmission</type>
        <joint name="imm1_mobile_joint_rotz">
            <hardwareInterface>hardware_interface/EffortJointInterface</hardwareInterface>
        </joint>
        <actuator name="imm1_mobile_joint_rotz_motor">
            <hardwareInterface>hardware_interface/EffortJointInterface</hardwareInterface>
            <mechanicalReduction>1</mechanicalReduction>
        </actuator>
    </transmission>
    <transmission name="trans_imm2_mobile_joint_traslx">
        <type>transmission_interface/SimpleTransmission</type>
        <joint name="imm2_mobile_joint_traslx">
            <hardwareInterface>hardware_interface/EffortJointInterface</hardwareInterface>
        </joint>
        <actuator name="imm2_mobile_joint_traslx_motor">
            <hardwareInterface>hardware_interface/EffortJointInterface</hardwareInterface>
            <mechanicalReduction>1</mechanicalReduction>
        </actuator>
    </transmission>
    <transmission name="trans_imm2_mobile_joint_trasly">
        <type>transmission_interface/SimpleTransmission</type>
        <joint name="imm2_mobile_joint_trasly">
            <hardwareInterface>hardware_interface/EffortJointInterface</hardwareInterface>
        </joint>
        <actuator name="imm2_mobile_joint_trasly_motor">
            <hardwareInterface>hardware_interface/EffortJointInterface</hardwareInterface>
            <mechanicalReduction>1</mechanicalReduction>
        </actuator>
    </transmission>
    <transmission name="trans_imm2_mobile_joint_rotz">
        <type>transmission_interface/SimpleTransmission</type>
        <joint name="imm2_mobile_joint_rotz">
            <hardwareInterface>hardware_interface/EffortJointInterface</hardwareInterface>
        </joint>
        <actuator name="imm2_mobile_joint_rotz_motor">
            <hardwareInterface>hardware_interface/EffortJointInterface</hardwareInterface>
            <mechanicalReduction>1</mechanicalReduction>
        </actuator>
    </transmission>
</robot>

